INFO:ours:|2024-08-24 16:43:32| {
     'att': 0, 'bs': 32, 'classification': False, 'cross': 0, 'dataset': cpu,
     'debug': False, 'decay': 0.0001, 'density': 0.8, 'device': cuda, 'device_name': core-i7-7820x,
     'epochs': 1000, 'eval_device': desktop-cpu-core-i9-13900k-fp32, 'experiment': False, 'graph_encoder': gat, 'heads': 8,
     'inductive': False, 'llm': 1, 'logger': None, 'loss_func': L1Loss, 'lr': 0.001,
     'model': ours, 'num_preds': 1, 'num_windows': 12, 'op_encoder': embed, 'optim': AdamW,
     'order': 4, 'path': ./datasets/, 'patience': 100, 'program_test': False, 'rank': 80,
     'record': True, 'rounds': 5, 'seed': 0, 'train_device': desktop-cpu-core-i7-7820x-fp32, 'train_size': 100,
     'verbose': 0, 'visualize': True,
}
INFO:ours:|2024-08-24 16:43:32| ********************Experiment Start********************
INFO:ours:|2024-08-24 16:44:03| Run 0 Error: Caught AttributeError in DataLoader worker process 1.
Original Traceback (most recent call last):
  File "train_model.py", line 135, in RunOnce
    model.load_state_dict(torch.load(model_path))
  File "/home/rtx4090/anaconda3/lib/python3.8/site-packages/torch/serialization.py", line 998, in load
    with _open_file_like(f, 'rb') as opened_file:
  File "/home/rtx4090/anaconda3/lib/python3.8/site-packages/torch/serialization.py", line 445, in _open_file_like
    return _open_file(name_or_buffer, mode)
  File "/home/rtx4090/anaconda3/lib/python3.8/site-packages/torch/serialization.py", line 426, in __init__
    super().__init__(open(name, mode))
FileNotFoundError: [Errno 2] No such file or directory: './checkpoints/ours/Model_ours_S100_R80_O4_round_0.pt'

During handling of the above exception, another exception occurred:

Traceback (most recent call last):
  File "/home/rtx4090/anaconda3/lib/python3.8/site-packages/torch/utils/data/_utils/worker.py", line 308, in _worker_loop
    data = fetcher.fetch(index)
  File "/home/rtx4090/anaconda3/lib/python3.8/site-packages/torch/utils/data/_utils/fetch.py", line 54, in fetch
    return self.collate_fn(data)
  File "/home/rtx4090/Code_python/LLM2024/data.py", line 180, in <lambda>
    collate_fn=lambda batch: custom_collate_fn(batch, args),
  File "/home/rtx4090/Code_python/LLM2024/data.py", line 148, in custom_collate_fn
    batched_graph = dgl.batch(graphs)
  File "/home/rtx4090/anaconda3/lib/python3.8/site-packages/dgl/batch.py", line 187, in batch
    bne[etype] = F.cat([g.batch_num_edges(etype) for g in graphs], 0)
  File "/home/rtx4090/anaconda3/lib/python3.8/site-packages/dgl/batch.py", line 187, in <listcomp>
    bne[etype] = F.cat([g.batch_num_edges(etype) for g in graphs], 0)
  File "/home/rtx4090/anaconda3/lib/python3.8/site-packages/dgl/heterograph.py", line 1664, in batch_num_edges
    F.tensor([self.num_edges(ty)], self.idtype), self.device
AttributeError: module 'dgl.backend' has no attribute '_batch_num_edges'
, This run will be skipped.
