INFO:ours:|2024-08-24 23:27:45| {
     'att': 0, 'bs': 32, 'classification': False, 'cross': 0, 'dataset': cpu,
     'debug': False, 'decay': 0.0001, 'density': 0.8, 'device': cuda, 'device_name': core-i7-7820x,
     'epochs': 1000, 'eval_device': desktop-cpu-core-i9-13900k-fp32, 'experiment': False, 'graph_encoder': gat, 'heads': 8,
     'inductive': False, 'llm': 1, 'logger': None, 'loss_func': L1Loss, 'lr': 0.001,
     'model': ours, 'num_preds': 1, 'num_windows': 12, 'op_encoder': embed, 'optim': AdamW,
     'order': 4, 'path': ./datasets/, 'patience': 100, 'program_test': False, 'rank': 140,
     'record': True, 'rounds': 5, 'seed': 0, 'train_device': desktop-cpu-core-i7-7820x-fp32, 'train_size': 500,
     'verbose': 0, 'visualize': True,
}
INFO:ours:|2024-08-24 23:27:45| ********************Experiment Start********************
INFO:ours:|2024-08-24 23:30:39| Run 0 Error: Caught ValueError in DataLoader worker process 5.
Original Traceback (most recent call last):
  File "train_model.py", line 135, in RunOnce
    model.load_state_dict(torch.load(model_path))
  File "/home/rtx4090/anaconda3/lib/python3.8/site-packages/torch/serialization.py", line 998, in load
    with _open_file_like(f, 'rb') as opened_file:
  File "/home/rtx4090/anaconda3/lib/python3.8/site-packages/torch/serialization.py", line 445, in _open_file_like
    return _open_file(name_or_buffer, mode)
  File "/home/rtx4090/anaconda3/lib/python3.8/site-packages/torch/serialization.py", line 426, in __init__
    super().__init__(open(name, mode))
FileNotFoundError: [Errno 2] No such file or directory: './checkpoints/ours/Model_ours_cpu_S500_R140_O4_round_0.pt'

During handling of the above exception, another exception occurred:

Traceback (most recent call last):
  File "/home/rtx4090/anaconda3/lib/python3.8/site-packages/torch/utils/data/_utils/worker.py", line 308, in _worker_loop
    data = fetcher.fetch(index)
  File "/home/rtx4090/anaconda3/lib/python3.8/site-packages/torch/utils/data/_utils/fetch.py", line 51, in fetch
    data = [self.dataset[idx] for idx in possibly_batched_index]
  File "/home/rtx4090/anaconda3/lib/python3.8/site-packages/torch/utils/data/_utils/fetch.py", line 51, in <listcomp>
    data = [self.dataset[idx] for idx in possibly_batched_index]
  File "/home/rtx4090/Code_python/LLM2024/data.py", line 115, in __getitem__
    graph = dgl.from_scipy(csr_matrix(graph))
  File "/home/rtx4090/anaconda3/lib/python3.8/site-packages/scipy/sparse/_compressed.py", line 85, in __init__
    self._coo_container(arg1, dtype=dtype)
  File "/home/rtx4090/anaconda3/lib/python3.8/site-packages/scipy/sparse/_coo.py", line 197, in __init__
    self._check()
  File "/home/rtx4090/anaconda3/lib/python3.8/site-packages/scipy/sparse/_coo.py", line 277, in _check
    idx_dtype = get_index_dtype(maxval=max(self.shape))
  File "/home/rtx4090/anaconda3/lib/python3.8/site-packages/scipy/sparse/_sputils.py", line 170, in get_index_dtype
    int32max = np.int32(np.iinfo(np.int32).max)
  File "/home/rtx4090/anaconda3/lib/python3.8/site-packages/numpy/core/getlimits.py", line 677, in __init__
    raise ValueError("Invalid integer data type %r." % (self.kind,))
ValueError: Invalid integer data type 'O'.
, This run will be skipped.
INFO:ours:|2024-08-24 23:34:12| Round=2 BestEpoch=373 MAE=0.0001 RMSE=0.0002 NMAE=0.0285 NRMSE=0.0456 Training_time=66.8 s 
INFO:ours:|2024-08-24 23:36:20| Round=3 BestEpoch=227 MAE=0.0002 RMSE=0.0003 NMAE=0.0324 NRMSE=0.0590 Training_time=41.0 s 
INFO:ours:|2024-08-24 23:39:53| Round=4 BestEpoch=452 MAE=0.0001 RMSE=0.0003 NMAE=0.0285 NRMSE=0.0485 Training_time=81.2 s 
INFO:ours:|2024-08-24 23:42:36| Round=5 BestEpoch=314 MAE=0.0002 RMSE=0.0004 NMAE=0.0370 NRMSE=0.0687 Training_time=57.2 s 
INFO:ours:|2024-08-24 23:42:36| ********************Experiment Results:********************
INFO:ours:|2024-08-24 23:42:36| MAE: 0.0002 ± 0.0000
INFO:ours:|2024-08-24 23:42:36| RMSE: 0.0003 ± 0.0000
INFO:ours:|2024-08-24 23:42:36| NMAE: 0.0316 ± 0.0035
INFO:ours:|2024-08-24 23:42:36| NRMSE: 0.0554 ± 0.0091
INFO:ours:|2024-08-24 23:42:36| Acc_1: 0.3732 ± 0.0103
INFO:ours:|2024-08-24 23:42:36| Acc_5: 0.8329 ± 0.0168
INFO:ours:|2024-08-24 23:42:36| Acc_10: 0.9447 ± 0.0126
INFO:ours:|2024-08-24 23:42:36| ********************Experiment Success********************
